2025-10-05 12:37:11,162 - app - INFO - Application starting up...
2025-10-05 12:37:11,162 - app - INFO - Starting server on port 5000...
2025-10-05 12:37:27,337 - app - INFO - [JS-INFO] Refreshed ROI list from server | data: {"count": 0, "ids": []}
2025-10-05 12:37:27,503 - app - ERROR - Could not list VmbPy cameras: Encountered an error loading Transport Layers during VmbStartup
Traceback (most recent call last):
  File "C:\Users\tinol\Git\labcamstreamer\.pixi\envs\default\Lib\site-packages\vmbpy\vmbsystem.py", line 500, in _startup
    call_vmb_c('VmbStartup', _as_vmb_file_path(self.__path_configuration))
    ~~~~~~~~~~^^^^^^^^^^^^^^^^^^^^^^^^^^^^^^^^^^^^^^^^^^^^^^^^^^^^^^^^^^^^
  File "C:\Users\tinol\Git\labcamstreamer\.pixi\envs\default\Lib\site-packages\vmbpy\util\tracer.py", line 146, in wrapper
    return func(*args, **kwargs)
  File "C:\Users\tinol\Git\labcamstreamer\.pixi\envs\default\Lib\site-packages\vmbpy\c_binding\vmb_c.py", line 907, in call_vmb_c
    getattr(_lib_instance, func_name)(*args)
    ~~~~~~~~~~~~~~~~~~~~~~~~~~~~~~~~~^^^^^^^
  File "C:\Users\tinol\Git\labcamstreamer\.pixi\envs\default\Lib\site-packages\vmbpy\c_binding\vmb_c.py", line 826, in _eval_vmberror
    raise VmbCError(result)
vmbpy.c_binding.vmb_common.VmbCError: VmbCError(<VmbError.NoTL: -16>)

The above exception was the direct cause of the following exception:

Traceback (most recent call last):
  File "C:\Users\tinol\Git\labcamstreamer\camera_service.py", line 147, in list_available_cameras
    with VmbSystem.get_instance() as vmb:
         ~~~~~~~~~~~~~~~~~~~~~~^^
  File "C:\Users\tinol\Git\labcamstreamer\.pixi\envs\default\Lib\site-packages\vmbpy\util\tracer.py", line 146, in wrapper
    return func(*args, **kwargs)
  File "C:\Users\tinol\Git\labcamstreamer\.pixi\envs\default\Lib\site-packages\vmbpy\vmbsystem.py", line 86, in __enter__
    self._startup()
    ~~~~~~~~~~~~~^^
  File "C:\Users\tinol\Git\labcamstreamer\.pixi\envs\default\Lib\site-packages\vmbpy\util\tracer.py", line 146, in wrapper
    return func(*args, **kwargs)
  File "C:\Users\tinol\Git\labcamstreamer\.pixi\envs\default\Lib\site-packages\vmbpy\util\context_decorator.py", line 50, in wrapper
    return func(*args, **kwargs)
  File "C:\Users\tinol\Git\labcamstreamer\.pixi\envs\default\Lib\site-packages\vmbpy\vmbsystem.py", line 511, in _startup
    raise Exc(msg) from e
vmbpy.error.VmbTransportLayerError: Encountered an error loading Transport Layers during VmbStartup
2025-10-05 12:37:32,030 - app - INFO - Camera START requested for ID: fake
2025-10-05 12:37:32,030 - app - INFO - Attempting to start camera: fake
2025-10-05 12:37:32,031 - app - INFO - Initializing FakeCamera...
2025-10-05 12:37:32,031 - app - INFO - FakeCamera: Starting stream...
2025-10-05 12:37:32,154 - app - INFO - FakeCamera started.
2025-10-05 12:37:32,674 - app - INFO - Frame size changed to (1280, 1024). Clamping ROIs.
2025-10-05 12:37:37,783 - app - INFO - [JS-INFO] Attempting to create ROI | data: {"rect": {"x": 780, "y": 94, "w": 324, "h": 202}}
2025-10-05 12:37:37,911 - app - INFO - [JS-INFO] Refreshed ROI list from server | data: {"count": 1, "ids": ["roi-1"]}
2025-10-05 12:37:39,471 - app - INFO - [JS-INFO] Attempting to create ROI | data: {"rect": {"x": 566, "y": 411, "w": 291, "h": 258}}
2025-10-05 12:37:39,931 - app - INFO - [JS-INFO] Refreshed ROI list from server | data: {"count": 2, "ids": ["roi-1", "roi-2"]}
2025-10-05 12:37:47,367 - app - INFO - [JS-INFO] Attempting to create ROI | data: {"rect": {"x": 233, "y": 198, "w": 282, "h": 219}}
2025-10-05 12:37:48,176 - app - INFO - [JS-INFO] Refreshed ROI list from server | data: {"count": 3, "ids": ["roi-1", "roi-2", "roi-3"]}
2025-10-05 12:37:55,446 - app - INFO - [JS-INFO] Refreshed ROI list from server | data: {"count": 3, "ids": ["roi-1", "roi-2", "roi-3"]}
2025-10-05 12:37:56,111 - app - INFO - [JS-INFO] Refreshed ROI list from server | data: {"count": 3, "ids": ["roi-1", "roi-2", "roi-3"]}
2025-10-05 12:37:56,410 - app - INFO - [JS-INFO] Refreshed ROI list from server | data: {"count": 3, "ids": ["roi-1", "roi-2", "roi-3"]}
